Workbook

Sheet Dashboard
A1: BetWarrior — Grupo Dupla (Affiliate ID 1476) — Performance Consolidada (R$)
A2: Consolidacao de sub-afiliados, funil por landing page e estrutura de custo (CPA + RevShare). Valores apenas em Reais.
A4: Premissas
A5: Cambio USD/BRL | B5: 5.15
A6: CPA unitario (R$) | B6: 160
A7: RevShare % (sobre Calculated NGR) | B7: 0.3
A9: Calculated NGR segue POSITIVO ha 4 atualizacoes seguidas (piso em zero nao esta sendo acionado). Volume de clicks e QFTD em crescimento continuo desde a primeira analise deste afiliado.
A11: Estrutura de Custo x Receita (Total do Afiliado)
A12: CPA Total (R$) = QFTD total x CPA unitario | B12: ='Sub-afiliados'!$R$25 -> 364640 | F12: Custo Total (R$) | G12: =B15 -> 370364.84
A13: Calculated NGR total do periodo (R$) = soma da coluna Calculated NGR | B13: ='Sub-afiliados'!$T$25 -> 19082.81 | F13: Net Revenue (R$) | G13: =B16 -> 79346.102
A14: RevShare (R$) = MAX(0; Calculated NGR x 30%) | B14: =MAX(0,B13*$B$7) -> 5724.843
A15: Custo Total da Operacao (R$) = CPA + RevShare | B15: =B12+B14 -> 370364.84
A16: Net Revenue do Relatorio (R$) | B16: ='Sub-afiliados'!$S$25 -> 79346.102
A17: % que o Net Revenue ja paga da operacao | B17: =IFERROR(B16/B15,0) -> 0.21423767
A19: KPIs Gerais
A20: Clicks | B20: ='Sub-afiliados'!$B$25 -> 184120
A21: Signups | B21: ='Sub-afiliados'!$C$25 -> 7488
A22: FTD (qtd) | B22: ='Sub-afiliados'!$D$25 -> 4421
A23: QFTD | B23: ='Sub-afiliados'!$E$25 -> 2279
A24: Conversao Total (Clique -> FTD) | B24: ='Sub-afiliados'!$F$25 -> 0.024011514
A25: Conversao QFTD (Clique -> QFTD) | B25: ='Sub-afiliados'!$G$25 -> 0.012377797
A26: Turnover Total (R$) | B26: ='Sub-afiliados'!$O$25 -> 484861.12
A27: Turnover Ratio Geral (Turnover/Deposito) | B27: ='Sub-afiliados'!$P$25 -> 1.5429996
A28: Cross-sell % Geral (Casino / Turnover Total) | B28: ='Sub-afiliados'!$Q$25 -> 0.18199439
A30: Graficos

Sheet Base Bruta
A1: Base Bruta — Dados originais do MyAffiliates (Grupo Dupla / Affiliate ID 1476)
A2: Mantida em US$ (moeda original do export) para auditoria. As demais abas desta versao mostram apenas R$.
A4: Nome da Campanha | B4: Sub-afiliado (Grupo) | C4: Landing Page | D4: LP ID | E4: Deal | F4: Clicks | G4: Signups | H4: Valor FTD (US$) | I4: Qtd FTD | J4: Depositos (US$) | K4: Saques (US$) | L4: Turnover Casino (US$) | M4: Casino Win Amount (US$) | N4: Turnover Sportsbook (US$) | O4: Net Revenue (US$) | P4: Calculated NGR (US$) | Q4: QFTD | R4: Earnings (Plataforma, US$) | S4: Incluido na Analise | T4: Motivo (se excluido)
A5: 0 | C5: - | D5: - | E5: R$160 CPA +30% Revenue Share - Dupla | F5: 0 | G5: 0 | H5: 0 | I5: 0 | J5: 0 | K5: 0 | L5: 0 | M5: 0 | N5: 0 | O5: 0 | P5: 0 | Q5: 0 | R5: 74039.62 | S5: Não | T5: Linha agregada de Earnings historico da plataforma, nao vinculada a atividade real (0 clicks). Earnings: $74039.62
A6: cabreloa | B6: Cabreloa | C6: AFF | Dupla Aposta | BR | D6: 311 | E6: R$160 CPA +30% Revenue Share - Dupla | F6: 782 | G6: 130 | H6: 614.14 | I6: 73 | J6: 935.99 | K6: 487.3 | L6: 38.81 | M6: 17.79 | N6: 463.33 | O6: 97.36 | P6: 18.52 | Q6: 42 | R6: 0 | S6: Sim
A7: cabreloa | B7: Cabreloa | C7: AFF BetSlip 2 | Dupla Aposta | BR | D7: 316 | E7: R$160 CPA +30% Revenue Share - Dupla | F7: 735 | G7: 10 | H7: 20.39 | I7: 7 | J7: 28.14 | K7: 0 | L7: 3.88 | M7: 2.02 | N7: 24.63 | O7: 26.48 | P7: 19.63 | Q7: 1 | R7: 0 | S7: Sim
A8: cabreloaboasvindas | B8: Cabreloa | C8: AFF BetSlip 2 | Dupla Aposta | BR | D8: 316 | E8: R$160 CPA +30% Revenue Share - Dupla | F8: 17 | G8: 0 | H8: 0 | I8: 0 | J8: 0 | K8: 0 | L8: 0 | M8: 0 | N8: 0 | O8: 0 | P8: 0 | Q8: 0 | R8: 0 | S8: Sim
A9: carlos ortega arena 01 | B9: Carlos Ortega Arena | C9: AFF | Dupla Aposta | BR | D9: 311 | E9: R$160 CPA +30% Revenue Share - Dupla | F9: 1 | G9: 0 | H9: 0 | I9: 0 | J9: 0 | K9: 0 | L9: 0 | M9: 0 | N9: 0 | O9: 0 | P9: 0 | Q9: 0 | R9: 0 | S9: Sim
A10: carlos ortega arena 01 | B10: Carlos Ortega Arena | C10: AFF BetSlip 2 | Dupla Aposta | BR | D10: 316 | E10: R$160 CPA +30% Revenue Share - Dupla | F10: 67 | G10: 1 | H10: 0 | I10: 0 | J10: 0 | K10: 0 | L10: 0 | M10: 0 | N10: 0 | O10: 0 | P10: 0 | Q10: 0 | R10: 0 | S10: Sim
A11: carlos ortega arena 03 | B11: Carlos Ortega Arena | C11: AFF | Dupla Aposta | BR | D11: 311 | E11: R$160 CPA +30% Revenue Share - Dupla | F11: 1 | G11: 0 | H11: 0 | I11: 0 | J11: 0 | K11: 0 | L11: 0 | M11: 0 | N11: 0 | O11: 0 | P11: 0 | Q11: 0 | R11: 0 | S11: Sim
A12: carlos ortega arena 04 | B12: Carlos Ortega Arena | C12: AFF BetSlip 2 | Dupla Aposta | BR | D12: 316 | E12: R$160 CPA +30% Revenue Share - Dupla | F12: 13 | G12: 0 | H12: 0 | I12: 0 | J12: 0 | K12: 0 | L12: 0 | M12: 0 | N12: 0 | O12: 0 | P12: 0 | Q12: 0 | R12: 0 | S12: Sim
A13: caumostats | B13: Mateus Caumo | C13: AFF | Dupla Aposta | BR | D13: 311 | E13: R$160 CPA +30% Revenue Share - Dupla | F13: 6 | G13: 0 | H13: 0 | I13: 0 | J13: 0 | K13: 0 | L13: 0 | M13: 0 | N13: 0 | O13: 0 | P13: 0 | Q13: 0 | R13: 0 | S13: Sim
A14: Comercial01Cabreloa | B14: Cabreloa | C14: AFF | Dupla Aposta | BR | D14: 311 | E14: R$160 CPA +30% Revenue Share - Dupla | F14: 11 | G14: 3 | H14: 6.79 | I14: 1 | J14: 6.79 | K14: 0 | L14: 0 | M14: 0 | N14: 6.79 | O14: 6.79 | P14: 5.02 | Q14: 1 | R14: 0 | S14: Sim
A15: Comercial01Cabreloa | B15: Cabreloa | C15: AFF BetSlip 2 | Dupla Aposta | BR | D15: 316 | E15: R$160 CPA +30% Revenue Share - Dupla | F15: 1 | G15: 0 | H15: 0 | I15: 0 | J15: 0 | K15: 0 | L15: 0 | M15: 0 | N15: 0 | O15: 0 | P15: 0 | Q15: 0 | R15: 0 | S15: Sim
A16: Comercial01WelingtondaBet | B16: Welington da Bet | C16: AFF | Dupla Aposta | BR | D16: 311 | E16: R$160 CPA +30% Revenue Share - Dupla | F16: 4 | G16: 1 | H16: 9.72 | I16: 1 | J16: 9.72 | K16: 0 | L16: 0 | M16: 0 | N16: 8.74 | O16: 8.74 | P16: 6.47 | Q16: 1 | R16: 0 | S16: Sim
A17: Comercial01WelingtondaBet | B17: Welington da Bet | C17: AFF BetSlip 2 | Dupla Aposta | BR | D17: 316 | E17: R$160 CPA +30% Revenue Share - Dupla | F17: 2 | G17: 0 | H17: 0 | I17: 0 | J17: 0 | K17: 0 | L17: 0 | M17: 0 | N17: 0 | O17: 0 | P17: 0 | Q17: 0 | R17: 0 | S17: Sim
... A89: mateuscaumocs | B89: Mateus Caumo | C89: AFF | Dupla Aposta | BR | D89: 311 | E89: R$160 CPA +30% Revenue Share - Dupla | F89: 10 | G89: 0 | H89: 0 | I89: 0 | J89: 0 | K89: 0 | L89: 0 | M89: 0 | N89: 0 | O89: 0 | P89: 0 | Q89: 0 | R89: 0 | S89: Sim
A90: mateuscaumocs | B90: Mateus Caumo | C90: AFF | Mail in Box | BR | D90: 312 | E90: R$160 CPA +30% Revenue Share - Dupla | F90: 1 | G90: 0 | H90: 0 | I90: 0 | J90: 0 | K90: 0 | L90: 0 | M90: 0 | N90: 0 | O90: 0 | P90: 0 | Q90: 0 | R90: 0 | S90: Não | T90: Landing page fora do escopo da analise (volume irrelevante)
A91: mateuscaumocs | B91: Mateus Caumo | C91: AFF BetSlip | Dupla Aposta | BR | D91: 313 | E91: R$160 CPA +30% Revenue Share - Dupla | F91: 14 | G91: 0 | H91: 0 | I91: 0 | J91: 0 | K91: 0 | L91: 0 | M91: 0 | N91: 0 | O91: 0 | P91: 0 | Q91: 0 | R91: 0 | S91: Sim
A92: mateuscaumocs | B92: Mateus Caumo | C92: AFF BetSlip 2 | Dupla Aposta | BR | D92: 316 | E92: R$160 CPA +30% Revenue Share - Dupla | F92: 8 | G92: 0 | H92: 0 | I92: 0 | J92: 0 | K92: 0 | L92: 0 | M92: 0 | N92: 0 | O92: 0 | P92: 0 | Q92: 0 | R92: 0 | S92: Sim
A93: mateuscaumoreg | B93: Mateus Caumo | C93: AFF | Dupla Aposta | BR | D93: 311 | E93: R$160 CPA +30% Revenue Share - Dupla | F93: 2127 | G93: 552 | H93: 4142.77 | I93: 415 | J93: 8704.62 | K93: 4304.68 | L93: 776.04 | M93: 728.4 | N93: 15489.19 | O93: 2287.43 | P93: 389.1 | Q93: 212 | R93: 0 | S93: Sim
A94: mateuscaumoreg | B94: Mateus Caumo | C94: AFF BetSlip 2 | Dupla Aposta | BR | D94: 316 | E94: R$160 CPA +30% Revenue Share - Dupla | F94: 17 | G94: 0 | H94: 0 | I94: 0 | J94: 0 | K94: 0 | L94: 0 | M94: 0 | N94: 0 | O94: 0 | P94: 0 | Q94: 0 | R94: 0 | S94: Sim
A95: mateuscaumotips | B95: Mateus Caumo | C95: AFF | Dupla Aposta | BR | D95: 311 | E95: R$160 CPA +30% Revenue Share - Dupla | F95: 5 | G95: 0 | H95: 0 | I95: 0 | J95: 0 | K95: 0 | L95: 0 | M95: 0 | N95: 0 | O95: 0 | P95: 0 | Q95: 0 | R95: 0 | S95: Sim
A96: menezes | B96: Menezes | C96: AFF | Dupla Aposta | BR | D96: 311 | E96: R$160 CPA +30% Revenue Share - Dupla | F96: 1 | G96: 0 | H96: 0 | I96: 0 | J96: 0 | K96: 0 | L96: 0 | M96: 0 | N96: 0 | O96: 0 | P96: 0 | Q96: 0 | R96: 0 | S96: Sim
A97: nathan brenner arena 01 | B97: Nathan Brenner Arena | C97: AFF | Dupla Aposta | BR | D97: 311 | E97: R$160 CPA +30% Revenue Share - Dupla | F97: 7 | G97: 2 | H97: 6.07 | I97: 1 | J97: 6.07 | K97: 6.03 | L97: 0 | M97: 0 | N97: 0 | O97: 0 | P97: 0 | Q97: 1 | R97: 0 | S97: Sim
A98: nathan brenner arena 01 | B98: Nathan Brenner Arena | C98: AFF BetSlip 2 | Dupla Aposta | BR | D98: 316 | E98: R$160 CPA +30% Revenue Share - Dupla | F98: 597 | G98: 17 | H98: 95.12 | I98: 12 | J98: 430.56 | K98: 104.49 | L98: 57.41 | M98: 27.77 | N98: 737.07 | O98: 245.13 | P98: 161.18 | Q98: 9 | R98: 0 | S98: Sim
A99: nathan brenner arena 02 | B99: Nathan Brenner Arena | C99: AFF | Dupla Aposta | BR | D99: 311 | E99: R$160 CPA +30% Revenue Share - Dupla | F99: 2 | G99: 0 | H99: 0 | I99: 0 | J99: 0 | K99: 0 | L99: 0 | M99: 0 | N99: 0 | O99: 0 | P99: 0 | Q99: 0 | R99: 0 | S99: Sim
A100: nathan brenner arena 02 | B100: Nathan Brenner Arena | C100: AFF BetSlip 2 | Dupla Aposta | BR | D100: 316 | E100: R$160 CPA +30% Revenue Share - Dupla | F100: 181 | G100: 0 | H100: 0 | I100: 0 | J100: 0 | K100: 0 | L100: 0 | M100: 0 | N100: 0 | O100: 0 | P100: 0 | Q100: 0 | R100: 0 | S100: Sim
A101: nathan brenner arena 03 | B101: Nathan Brenner Arena | C101: AFF BetSlip 2 | Dupla Aposta | BR | D101: 316 | E101: R$160 CPA +30% Revenue Share - Dupla | F101: 76 | G101: 4 | H101: 0 | I101: 0 | J101: 0 | K101: 0 | L101: 0 | M101: 0 | N101: 0 | O101: 0 | P101: 0 | Q101: 0 | R101: 0 | S101: Sim
A102: nathan brenner arena 04 | B102: Nathan Brenner Arena | C102: AFF BetSlip 2 | Dupla Aposta | BR | D102: 316 | E102: R$160 CPA +30% Revenue Share - Dupla | F102: 56 | G102: 2 | H102: 3.88 | I102: 2 | J102: 8.73 | K102: 3.89 | L102: 0 | M102: 0 | N102: 4.83 | O102: 4.83 | P102: 3.58 | Q102: 0 | R102: 0 | S102: Sim
... A135: telles04 | B135: Telles | C135: AFF | Dupla Aposta | BR | D135: 311 | E135: R$160 CPA +30% Revenue Share - Dupla | F135: 31 | G135: 4 | H135: 0 | I135: 0 | J135: 0 | K135: 0 | L135: 0 | M135: 0 | N135: 0 | O135: 0 | P135: 0 | Q135: 0 | R135: 0 | S135: Sim
A136: testelink | C136: AFF BetSlip 2 | Dupla Aposta | BR | D136: 316 | E136: R$160 CPA +30% Revenue Share - Dupla | F136: 1 | G136: 0 | H136: 0 | I136: 0 | J136: 0 | K136: 0 | L136: 0 | M136: 0 | N136: 0 | O136: 0 | P136: 0 | Q136: 0 | R136: 0 | S136: Não | T136: Link de teste interno, nao e um sub-afiliado real
A137: Thierry1 | B137: Thierry | C137: AFF | Dupla Aposta | BR | D137: 311 | E137: R$160 CPA +30% Revenue Share - Dupla | F137: 3 | G137: 0 | H137: 0 | I137: 0 | J137: 0 | K137: 0 | L137: 0 | M137: 0 | N137: 0 | O137: 0 | P137: 0 | Q137: 0 | R137: 0 | S137: Sim
A138: Thierry1 | B138: Thierry | C138: AFF BetSlip 2 | Dupla Aposta | BR | D138: 316 | E138: R$160 CPA +30% Revenue Share - Dupla | F138: 173 | G138: 7 | H138: 17.48 | I138: 5 | J138: 29.32 | K138: 0 | L138: 0 | M138: 0 | N138: 31.42 | O138: 26.19 | P138: 19.29 | Q138: 2 | R138: 0 | S138: Sim
A139: Thierry3 | B139: Thierry | C139: AFF | Dupla Aposta | BR | D139: 311 | E139: R$160 CPA +30% Revenue Share - Dupla | F139: 1518 | G139: 423 | H139: 1277.01 | I139: 231 | J139: 2776.93 | K139: 540.35 | L139: 662.83 | M139: 513.52 | N139: 2676.6 | O139: 1923.51 | P139: 1339.1 | Q139: 115 | R139: 0 | S139: Sim
A140: Thierry3 | B140: Thierry | C140: AFF BetSlip 2 | Dupla Aposta | BR | D140: 316 | E140: R$160 CPA +30% Revenue Share - Dupla | F140: 12270 | G140: 571 | H140: 3493.26 | I140: 408 | J140: 5499.78 | K140: 2685.17 | L140: 2245.49 | M140: 2264.55 | N140: 5984.64 | O140: 1299.12 | P140: 417.13 | Q140: 178 | R140: 0 | S140: Sim
A141: Thierry4 | B141: Thierry | C141: AFF | Dupla Aposta | BR | D141: 311 | E141: R$160 CPA +30% Revenue Share - Dupla | F141: 1 | G141: 0 | H141: 0 | I141: 0 | J141: 0 | K141: 0 | L141: 0 | M141: 0 | N141: 0 | O141: 0 | P141: 0 | Q141: 0 | R141: 0 | S141: Sim
A142: Thierry4 | B142: Thierry | C142: AFF BetSlip 2 | Dupla Aposta | BR | D142: 316 | E142: R$160 CPA +30% Revenue Share - Dupla | F142: 1 | G142: 0 | H142: 0 | I142: 0 | J142: 0 | K142: 0 | L142: 0 | M142: 0 | N142: 0 | O142: 0 | P142: 0 | Q142: 0 | R142: 0 | S142: Sim
A143: welingtondabet | B143: Welington da Bet | C143: AFF | Dupla Aposta | BR | D143: 311 | E143: R$160 CPA +30% Revenue Share - Dupla | F143: 209 | G143: 33 | H143: 68.16 | I143: 6 | J143: 70.1 | K143: 19.6 | L143: 203.55 | M143: 168.69 | N143: 20.68 | O143: 52.31 | P143: 34.93 | Q143: 2 | R143: 0 | S143: Sim
A144: welingtondabet | B144: Welington da Bet | C144: AFF BetSlip 2 | Dupla Aposta | BR | D144: 316 | E144: R$160 CPA +30% Revenue Share - Dupla | F144: 51 | G144: 4 | H144: 14.48 | I144: 2 | J144: 27.01 | K144: 35.49 | L144: 0 | M144: 0 | N144: 24.12 | O144: -8.53 | P144: -11.3 | Q144: 2 | R144: 0 | S144: Sim
...

Sheet Sub-afiliados
A1: Performance Consolidada por Sub-afiliado — Grupo Dupla (valores em R$)
A2: Versao apenas em Reais. Fonte (Base Bruta) permanece em US$; conversao pelo cambio em Dashboard.
A4: Sub-afiliado | B4: Clicks | C4: Signups | D4: FTD (qtd) | E4: QFTD | F4: Conv. Total (Clique->FTD) | G4: Conv. QFTD (Clique->QFTD) | H4: Valor FTD (R$) | I4: Deposito Total (R$) | J4: Ticket Medio FTD (R$) | K4: Ticket Medio Dep. Total (R$) | L4: Redeposito (R$) | M4: Turnover Casino (R$) | N4: Turnover Sportsbook (R$) | O4: Turnover Total (R$) | P4: Turnover Ratio (Turnover/Deposito) | Q4: Cross-sell % (Casino/Turnover) | R4: CPA (R$) | S4: Net Revenue (R$) | T4: Calculated NGR (R$)
A5: Cabreloa | B5: =SUMIFS('Base Bruta'!$F$5:$F$145,'Base Bruta'!$B$5:$B$145,$A5,'Base Bruta'!$S$5:$S$145,"Sim") -> 1574 | C5: =SUMIFS('Base Bruta'!$G$5:$G$145,'Base Bruta'!$B$5:$B$145,$A5,'Base Bruta'!$S$5:$S$145,"Sim") -> 149 | D5: =SUMIFS('Base Bruta'!$I$5:$I$145,'Base Bruta'!$B$5:$B$145,$A5,'Base Bruta'!$S$5:$S$145,"Sim") -> 85 | E5: =SUMIFS('Base Bruta'!$Q$5:$Q$145,'Base Bruta'!$B$5:$B$145,$A5,'Base Bruta'!$S$5:$S$145,"Sim") -> 48 | F5: =IFERROR(D5/B5,0) -> 0.054002541 | G5: =IFERROR(E5/B5,0) -> 0.030495553 | H5: =SUMIFS('Base Bruta'!$H$5:$H$145,'Base Bruta'!$B$5:$B$145,$A5,'Base Bruta'!$S$5:$S$145,"Sim")*Dashboard!$B$5 -> 3441.745 | I5: =SUMIFS('Base Bruta'!$J$5:$J$145,'Base Bruta'!$B$5:$B$145,$A5,'Base Bruta'!$S$5:$S$145,"Sim")*Dashboard!$B$5 -> 5139.185 | J5: =IFERROR(H5/D5,0) -> 40.491118 | K5: =IFERROR(I5/D5,0) -> 60.461 | L5: =I5-H5 -> 1697.44 | M5: =SUMIFS('Base Bruta'!$L$5:$L$145,'Base Bruta'!$B$5:$B$145,$A5,'Base Bruta'!$S$5:$S$145,"Sim")*Dashboard!$B$5 -> 219.8535 | N5: =SUMIFS('Base Bruta'!$N$5:$N$145,'Base Bruta'!$B$5:$B$145,$A5,'Base Bruta'!$S$5:$S$145,"Sim")*Dashboard!$B$5 -> 2734.1865 | O5: =M5+N5 -> 2954.04 | P5: =IFERROR(O5/I5,0) -> 0.57480709 | Q5: =IFERROR(M5/O5,0) -> 0.074424686 | R5: =E5*Dashboard!$B$6 -> 7680 | S5: =SUMIFS('Base Bruta'!$O$5:$O$145,'Base Bruta'!$B$5:$B$145,$A5,'Base Bruta'!$S$5:$S$145,"Sim")*Dashboard!$B$5 -> 780.431 | T5: =SUMIFS('Base Bruta'!$P$5:$P$145,'Base Bruta'!$B$5:$B$145,$A5,'Base Bruta'!$S$5:$S$145,"Sim")*Dashboard!$B$5 -> 293.9105
A6: Carlos Ortega Arena | B6: =SUMIFS('Base Bruta'!$F$5:$F$145,'Base Bruta'!$B$5:$B$145,$A6,'Base Bruta'!$S$5:$S$145,"Sim") -> 82 | C6: =SUMIFS('Base Bruta'!$G$5:$G$145,'Base Bruta'!$B$5:$B$145,$A6,'Base Bruta'!$S$5:$S$145,"Sim") -> 1 | D6: =SUMIFS('Base Bruta'!$I$5:$I$145,'Base Bruta'!$B$5:$B$145,$A6,'Base Bruta'!$S$5:$S$145,"Sim") -> 0 | E6: =SUMIFS('Base Bruta'!$Q$5:$Q$145,'Base Bruta'!$B$5:$B$145,$A6,'Base Bruta'!$S$5:$S$145,"Sim") -> 0 | F6: =IFERROR(D6/B6,0) -> 0 | G6: =IFERROR(E6/B6,0) -> 0 | H6: =SUMIFS('Base Bruta'!$H$5:$H$145,'Base Bruta'!$B$5:$B$145,$A6,'Base Bruta'!$S$5:$S$145,"Sim")*Dashboard!$B$5 -> 0 | I6: =SUMIFS('Base Bruta'!$J$5:$J$145,'Base Bruta'!$B$5:$B$145,$A6,'Base Bruta'!$S$5:$S$145,"Sim")*Dashboard!$B$5 -> 0 | J6: =IFERROR(H6/D6,0) -> 0 | K6: =IFERROR(I6/D6,0) -> 0 | L6: =I6-H6 -> 0 | M6: =SUMIFS('Base Bruta'!$L$5:$L$145,'Base Bruta'!$B$5:$B$145,$A6,'Base Bruta'!$S$5:$S$145,"Sim")*Dashboard!$B$5 -> 0 | N6: =SUMIFS('Base Bruta'!$N$5:$N$145,'Base Bruta'!$B$5:$B$145,$A6,'Base Bruta'!$S$5:$S$145,"Sim")*Dashboard!$B$5 -> 0 | O6: =M6+N6 -> 0 | P6: =IFERROR(O6/I6,0) -> 0 | Q6: =IFERROR(M6/O6,0) -> 0 | R6: =E6*Dashboard!$B$6 -> 0 | S6: =SUMIFS('Base Bruta'!$O$5:$O$145,'Base Bruta'!$B$5:$B$145,$A6,'Base Bruta'!$S$5:$S$145,"Sim")*Dashboard!$B$5 -> 0 | T6: =SUMIFS('Base Bruta'!$P$5:$P$145,'Base Bruta'!$B$5:$B$145,$A6,'Base Bruta'!$S$5:$S$145,"Sim")*Dashboard!$B$5 -> 0
A7: DG Arena | B7: =SUMIFS('Base Bruta'!$F$5:$F$145,'Base Bruta'!$B$5:$B$145,$A7,'Base Bruta'!$S$5:$S$145,"Sim") -> 1338 | C7: =SUMIFS('Base Bruta'!$G$5:$G$145,'Base Bruta'!$B$5:$B$145,$A7,'Base Bruta'!$S$5:$S$145,"Sim") -> 27 | D7: =SUMIFS('Base Bruta'!$I$5:$I$145,'Base Bruta'!$B$5:$B$145,$A7,'Base Bruta'!$S$5:$S$145,"Sim") -> 8 | E7: =SUMIFS('Base Bruta'!$Q$5:$Q$145,'Base Bruta'!$B$5:$B$145,$A7,'Base Bruta'!$S$5:$S$145,"Sim") -> 1 | F7: =IFERROR(D7/B7,0) -> 0.0059790732 | G7: =IFERROR(E7/B7,0) -> 0.00074738416 | H7: =SUMIFS('Base Bruta'!$H$5:$H$145,'Base Bruta'!$B$5:$B$145,$A7,'Base Bruta'!$S$5:$S$145,"Sim")*Dashboard!$B$5 -> 89.919 | I7: =SUMIFS('Base Bruta'!$J$5:$J$145,'Base Bruta'!$B$5:$B$145,$A7,'Base Bruta'!$S$5:$S$145,"Sim")*Dashboard!$B$5 -> 139.874 | J7: =IFERROR(H7/D7,0) -> 11.239875 | K7: =IFERROR(I7/D7,0) -> 17.48425 | L7: =I7-H7 -> 49.955 | M7: =SUMIFS('Base Bruta'!$L$5:$L$145,'Base Bruta'!$B$5:$B$145,$A7,'Base Bruta'!$S$5:$S$145,"Sim")*Dashboard!$B$5 -> 0.4635 | N7: =SUMIFS('Base Bruta'!$N$5:$N$145,'Base Bruta'!$B$5:$B$145,$A7,'Base Bruta'!$S$5:$S$145,"Sim")*Dashboard!$B$5 -> 138.9985 | O7: =M7+N7 -> 139.462 | P7: =IFERROR(O7/I7,0) -> 0.99705449 | Q7: =IFERROR(M7/O7,0) -> 0.003323486 | R7: =E7*Dashboard!$B$6 -> 160 | S7: =SUMIFS('Base Bruta'!$O$5:$O$145,'Base Bruta'!$B$5:$B$145,$A7,'Base Bruta'!$S$5:$S$145,"Sim")*Dashboard!$B$5 -> 109.5405 | T7: =SUMIFS('Base Bruta'!$P$5:$P$145,'Base Bruta'!$B$5:$B$145,$A7,'Base Bruta'!$S$5:$S$145,"Sim")*Dashboard!$B$5 -> 73.439
A8: Doria Arena | B8: =SUMIFS('Base Bruta'!$F$5:$F$145,'Base Bruta'!$B$5:$B$145,$A8,'Base Bruta'!$S$5:$S$145,"Sim") -> 676 | C8: =SUMIFS('Base Bruta'!$G$5:$G$145,'Base Bruta'!$B$5:$B$145,$A8,'Base Bruta'!$S$5:$S$145,"Sim") -> 62 | D8: =SUMIFS('Base Bruta'!$I$5:$I$145,'Base Bruta'!$B$5:$B$145,$A8,'Base Bruta'!$S$5:$S$145,"Sim") -> 20 | E8: =SUMIFS('Base Bruta'!$Q$5:$Q$145,'Base Bruta'!$B$5:$B$145,$A8,'Base Bruta'!$S$5:$S$145,"Sim") -> 12 | F8: =IFERROR(D8/B8,0) -> 0.029585799 | G8: =IFERROR(E8/B8,0) -> 0.017751479 | H8: =SUMIFS('Base Bruta'!$H$5:$H$145,'Base Bruta'!$B$5:$B$145,$A8,'Base Bruta'!$S$5:$S$145,"Sim")*Dashboard!$B$5 -> 534.7245 | I8: =SUMIFS('Base Bruta'!$J$5:$J$145,'Base Bruta'!$B$5:$B$145,$A8,'Base Bruta'!$S$5:$S$145,"Sim")*Dashboard!$B$5 -> 594.722 | J8: =IFERROR(H8/D8,0) -> 26.736225 | K8: =IFERROR(I8/D8,0) -> 29.7361 | L8: =I8-H8 -> 59.9975 | M8: =SUMIFS('Base Bruta'!$L$5:$L$145,'Base Bruta'!$B$5:$B$145,$A8,'Base Bruta'!$S$5:$S$145,"Sim")*Dashboard!$B$5 -> 29.87 | N8: =SUMIFS('Base Bruta'!$N$5:$N$145,'Base Bruta'!$B$5:$B$145,$A8,'Base Bruta'!$S$5:$S$145,"Sim")*Dashboard!$B$5 -> 430.54 | O8: =M8+N8 -> 460.41 | P8: =IFERROR(O8/I8,0) -> 0.77416003 | Q8: =IFERROR(M8/O8,0) -> 0.064876957 | R8: =E8*Dashboard!$B$6 -> 1920 | S8: =SUMIFS('Base Bruta'!$O$5:$O$145,'Base Bruta'!$B$5:$B$145,$A8,'Base Bruta'!$S$5:$S$145,"Sim")*Dashboard!$B$5 -> 198.687 | T8: =SUMIFS('Base Bruta'!$P$5:$P$145,'Base Bruta'!$B$5:$B$145,$A8,'Base Bruta'!$S$5:$S$145,"Sim")*Dashboard!$B$5 -> 120.716
A9: Dupla Aposta | B9: =SUMIFS('Base Bruta'!$F$5:$F$145,'Base Bruta'!$B$5:$B$145,$A9,'Base Bruta'!$S$5:$S$145,"Sim") -> 636 | C9: =SUMIFS('Base Bruta'!$G$5:$G$145,'Base Bruta'!$B$5:$B$145,$A9,'Base Bruta'!$S$5:$S$145,"Sim") -> 23 | D9: =SUMIFS('Base Bruta'!$I$5:$I$145,'Base Bruta'!$B$5:$B$145,$A9,'Base Bruta'!$S$5:$S$145,"Sim") -> 18 | E9: =SUMIFS('Base Bruta'!$Q$5:$Q$145,'Base Bruta'!$B$5:$B$145,$A9,'Base Bruta'!$S$5:$S$145,"Sim") -> 17 | F9: =IFERROR(D9/B9,0) -> 0.028301887 | G9: =IFERROR(E9/B9,0) -> 0.02672956 | H9: =SUMIFS('Base Bruta'!$H$5:$H$145,'Base Bruta'!$B$5:$B$145,$A9,'Base Bruta'!$S$5:$S$145,"Sim")*Dashboard!$B$5 -> 669.5515 | I9: =SUMIFS('Base Bruta'!$J$5:$J$145,'Base Bruta'!$B$5:$B$145,$A9,'Base Bruta'!$S$5:$S$145,"Sim")*Dashboard!$B$5 -> 1032.987 | J9: =IFERROR(H9/D9,0) -> 37.197306 | K9: =IFERROR(I9/D9,0) -> 57.388167 | L9: =I9-H9 -> 363.4355 | M9: =SUMIFS('Base Bruta'!$L$5:$L$145,'Base Bruta'!$B$5:$B$145,$A9,'Base Bruta'!$S$5:$S$145,"Sim")*Dashboard!$B$5 -> 0 | N9: =SUMIFS('Base Bruta'!$N$5:$N$145,'Base Bruta'!$B$5:$B$145,$A9,'Base Bruta'!$S$5:$S$145,"Sim")*Dashboard!$B$5 -> 1335.395 | O9: =M9+N9 -> 1335.395 | P9: =IFERROR(O9/I9,0) -> 1.292751 | Q9: =IFERROR(M9/O9,0) -> 0 | R9: =E9*Dashboard!$B$6 -> 2720 | S9: =SUMIFS('Base Bruta'!$O$5:$O$145,'Base Bruta'!$B$5:$B$145,$A9,'Base Bruta'!$S$5:$S$145,"Sim")*Dashboard!$B$5 -> 176.7995 | T9: =SUMIFS('Base Bruta'!$P$5:$P$145,'Base Bruta'!$B$5:$B$145,$A9,'Base Bruta'!$S$5:$S$145,"Sim")*Dashboard!$B$5 -> -43.981
A10: Emilio | B10: =SUMIFS('Base Bruta'!$F$5:$F$145,'Base Bruta'!$B$5:$B$145,$A10,'Base Bruta'!$S$5:$S$145,"Sim") -> 31254 | C10: =SUMIFS('Base Bruta'!$G$5:$G$145,'Base Bruta'!$B$5:$B$145,$A10,'Base Bruta'!$S$5:$S$145,"Sim") -> 1018 | D10: =SUMIFS('Base Bruta'!$I$5:$I$145,'Base Bruta'!$B$5:$B$145,$A10,'Base Bruta'!$S$5:$S$145,"Sim") -> 521 | E10: =SUMIFS('Base Bruta'!$Q$5:$Q$145,'Base Bruta'!$B$5:$B$145,$A10,'Base Bruta'!$S$5:$S$145,"Sim") -> 273 | F10: =IFERROR(D10/B10,0) -> 0.016669866 | G10: =IFERROR(E10/B10,0) -> 0.0087348819 | H10: =SUMIFS('Base Bruta'!$H$5:$H$145,'Base Bruta'!$B$5:$B$145,$A10,'Base Bruta'!$S$5:$S$145,"Sim")*Dashboard!$B$5 -> 12954.773 | I10: =SUMIFS('Base Bruta'!$J$5:$J$145,'Base Bruta'!$B$5:$B$145,$A10,'Base Bruta'!$S$5:$S$145,"Sim")*Dashboard!$B$5 -> 25653.592 | J10: =IFERROR(H10/D10,0) -> 24.865208 | K10: =IFERROR(I10/D10,0) -> 49.23914 | L10: =I10-H10 -> 12698.818 | M10: =SUMIFS('Base Bruta'!$L$5:$L$145,'Base Bruta'!$B$5:$B$145,$A10,'Base Bruta'!$S$5:$S$145,"Sim")*Dashboard!$B$5 -> 7206.498 | N10: =SUMIFS('Base Bruta'!$N$5:$N$145,'Base Bruta'!$B$5:$B$145,$A10,'Base Bruta'!$S$5:$S$145,"Sim")*Dashboard!$B$5 -> 23856.088 | O10: =M10+N10 -> 31062.586 | P10: =IFERROR(O10/I10,0) -> 1.2108474 | Q10: =IFERROR(M10/O10,0) -> 0.2319993 | R10: =E10*Dashboard!$B$6 -> 43680 | S10: =SUMIFS('Base Bruta'!$O$5:$O$145,'Base Bruta'!$B$5:$B$145,$A10,'Base Bruta'!$S$5:$S$145,"Sim")*Dashboard!$B$5 -> 13136.517 | T10: =SUMIFS('Base Bruta'!$P$5:$P$145,'Base Bruta'!$B$5:$B$145,$A10,'Base Bruta'!$S$5:$S$145,"Sim")*Dashboard!$B$5 -> 8531.7475
A11: Igorsa Arena | B11: =SUMIFS('Base Bruta'!$F$5:$F$145,'Base Bruta'!$B$5:$B$145,$A11,'Base Bruta'!$S$5:$S$145,"Sim") -> 21613 | C11: =SUMIFS('Base Bruta'!$G$5:$G$145,'Base Bruta'!$B$5:$B$145,$A11,'Base Bruta'!$S$5:$S$145,"Sim") -> 433 | D11: =SUMIFS('Base Bruta'!$I$5:$I$145,'Base Bruta'!$B$5:$B$145,$A11,'Base Bruta'!$S$5:$S$145,"Sim") -> 247 | E11: =SUMIFS('Base Bruta'!$Q$5:$Q$145,'Base Bruta'!$B$5:$B$145,$A11,'Base Bruta'!$S$5:$S$145,"Sim") -> 130 | F11: =IFERROR(D11/B11,0) -> 0.011428307 | G11: =IFERROR(E11/B11,0) -> 0.0060148984 | H11: =SUMIFS('Base Bruta'!$H$5:$H$145,'Base Bruta'!$B$5:$B$145,$A11,'Base Bruta'!$S$5:$S$145,"Sim")*Dashboard!$B$5 -> 6230.47 | I11: =SUMIFS('Base Bruta'!$J$5:$J$145,'Base Bruta'!$B$5:$B$145,$A11,'Base Bruta'!$S$5:$S$145,"Sim")*Dashboard!$B$5 -> 10635.832 | J11: =IFERROR(H11/D11,0) -> 25.224575 | K11: =IFERROR(I11/D11,0) -> 43.060047 | L11: =I11-H11 -> 4405.3615 | M11: =SUMIFS('Base Bruta'!$L$5:$L$145,'Base Bruta'!$B$5:$B$145,$A11,'Base Bruta'!$S$5:$S$145,"Sim")*Dashboard!$B$5 -> 2551.516 | N11: =SUMIFS('Base Bruta'!$N$5:$N$145,'Base Bruta'!$B$5:$B$145,$A11,'Base Bruta'!$S$5:$S$145,"Sim")*Dashboard!$B$5 -> 23443.933 | O11: =M11+N11 -> 25995.449 | P11: =IFERROR(O11/I11,0) -> 2.4441389 | Q11: =IFERROR(M11/O11,0) -> 0.098152411 | R11: =E11*Dashboard!$B$6 -> 20800 | S11: =SUMIFS('Base Bruta'!$O$5:$O$145,'Base Bruta'!$B$5:$B$145,$A11,'Base Bruta'!$S$5:$S$145,"Sim")*Dashboard!$B$5 -> 11713.727 | T11: =SUMIFS('Base Bruta'!$P$5:$P$145,'Base Bruta'!$B$5:$B$145,$A11,'Base Bruta'!$S$5:$S$145,"Sim")*Dashboard!$B$5 -> 7360.998
A12: Lucao NBA Arena | B12: =SUMIFS('Base Bruta'!$F$5:$F$145,'Base Bruta'!$B$5:$B$145,$A12,'Base Bruta'!$S$5:$S$145,"Sim") -> 3851 | C12: =SUMIFS('Base Bruta'!$G$5:$G$145,'Base Bruta'!$B$5:$B$145,$A12,'Base Bruta'!$S$5:$S$145,"Sim") -> 31 | D12: =SUMIFS('Base Bruta'!$I$5:$I$145,'Base Bruta'!$B$5:$B$145,$A12,'Base Bruta'!$S$5:$S$145,"Sim") -> 17 | E12: =SUMIFS('Base Bruta'!$Q$5:$Q$145,'Base Bruta'!$B$5:$B$145,$A12,'Base Bruta'!$S$5:$S$145,"Sim") -> 11 | F12: =IFERROR(D12/B12,0) -> 0.0044144378 | G12: =IFERROR(E12/B12,0) -> 0.0028564009 | H12: =SUMIFS('Base Bruta'!$H$5:$H$145,'Base Bruta'!$B$5:$B$145,$A12,'Base Bruta'!$S$5:$S$145,"Sim")*Dashboard!$B$5 -> 769.5645 | I12: =SUMIFS('Base Bruta'!$J$5:$J$145,'Base Bruta'!$B$5:$B$145,$A12,'Base Bruta'!$S$5:$S$145,"Sim")*Dashboard!$B$5 -> 1574.9215 | J12: =IFERROR(H12/D12,0) -> 45.2685 | K12: =IFERROR(I12/D12,0) -> 92.642441 | L12: =I12-H12 -> 805.357 | M12: =SUMIFS('Base Bruta'!$L$5:$L$145,'Base Bruta'!$B$5:$B$145,$A12,'Base Bruta'!$S$5:$S$145,"Sim")*Dashboard!$B$5 -> 48.9765 | N12: =SUMIFS('Base Bruta'!$N$5:$N$145,'Base Bruta'!$B$5:$B$145,$A12,'Base Bruta'!$S$5:$S$145,"Sim")*Dashboard!$B$5 -> 1669.6815 | O12: =M12+N12 -> 1718.658 | P12: =IFERROR(O12/I12,0) -> 1.0912658 | Q12: =IFERROR(M12/O12,0) -> 0.028496944 | R12: =E12*Dashboard!$B$6 -> 1760 | S12: =SUMIFS('Base Bruta'!$O$5:$O$145,'Base Bruta'!$B$5:$B$145,$A12,'Base Bruta'!$S$5:$S$145,"Sim")*Dashboard!$B$5 -> 366.2165 | T12: =SUMIFS('Base Bruta'!$P$5:$P$145,'Base Bruta'!$B$5:$B$145,$A12,'Base Bruta'!$S$5:$S$145,"Sim")*Dashboard!$B$5 -> 72.0485
A13: Magreen | B13: =SUMIFS('Base Bruta'!$F$5:$F$145,'Base Bruta'!$B$5:$B$145,$A13,'Base Bruta'!$S$5:$S$145,"Sim") -> 7137 | C13: =SUMIFS('Base Bruta'!$G$5:$G$145,'Base Bruta'!$B$5:$B$145,$A13,'Base Bruta'!$S$5:$S$145,"Sim") -> 223 | D13: =SUMIFS('Base Bruta'!$I$5:$I$145,'Base Bruta'!$B$5:$B$145,$A13,'Base Bruta'!$S$5:$S$145,"Sim") -> 125 | E13: =SUMIFS('Base Bruta'!$Q$5:$Q$145,'Base Bruta'!$B$5:$B$145,$A13,'Base Bruta'!$S$5:$S$145,"Sim") -> 54 | F13: =IFERROR(D13/B13,0) -> 0.017514362 | G13: =IFERROR(E13/B13,0) -> 0.0075662043 | H13: =SUMIFS('Base Bruta'!$H$5:$H$145,'Base Bruta'!$B$5:$B$145,$A13,'Base Bruta'!$S$5:$S$145,"Sim")*Dashboard!$B$5 -> 7923.0175 | I13: =SUMIFS('Base Bruta'!$J$5:$J$145,'Base Bruta'!$B$5:$B$145,$A13,'Base Bruta'!$S$5:$S$145,"Sim")*Dashboard!$B$5 -> 11145.218 | J13: =IFERROR(H13/D13,0) -> 63.38414 | K13: =IFERROR(I13/D13,0) -> 89.161744 | L13: =I13-H13 -> 3222.2005 | M13: =SUMIFS('Base Bruta'!$L$5:$L$145,'Base Bruta'!$B$5:$B$145,$A13,'Base Bruta'!$S$5:$S$145,"Sim")*Dashboard!$B$5 -> 780.534 | N13: =SUMIFS('Base Bruta'!$N$5:$N$145,'Base Bruta'!$B$5:$B$145,$A13,'Base Bruta'!$S$5:$S$145,"Sim")*Dashboard!$B$5 -> 14403.984 | O13: =M13+N13 -> 15184.517 | P13: =IFERROR(O13/I13,0) -> 1.3624244 | Q13: =IFERROR(M13/O13,0) -> 0.05140328 | R13: =E13*Dashboard!$B$6 -> 8640 | S13: =SUMIFS('Base Bruta'!$O$5:$O$145,'Base Bruta'!$B$5:$B$145,$A13,'Base Bruta'!$S$5:$S$145,"Sim")*Dashboard!$B$5 -> 2175.463 | T13: =SUMIFS('Base Bruta'!$P$5:$P$145,'Base Bruta'!$B$5:$B$145,$A13,'Base Bruta'!$S$5:$S$145,"Sim")*Dashboard!$B$5 -> 290.8205
A14: Mariatips | B14: =SUMIFS('Base Bruta'!$F$5:$F$145,'Base Bruta'!$B$5:$B$145,$A14,'Base Bruta'!$S$5:$S$145,"Sim") -> 3 | C14: =SUMIFS('Base Bruta'!$G$5:$G$145,'Base Bruta'!$B$5:$B$145,$A14,'Base Bruta'!$S$5:$S$145,"Sim") -> 0 | D14: =SUMIFS('Base Bruta'!$I$5:$I$145,'Base Bruta'!$B$5:$B$145,$A14,'Base Bruta'!$S$5:$S$145,"Sim") -> 0 | E14: =SUMIFS('Base Bruta'!$Q$5:$Q$145,'Base Bruta'!$B$5:$B$145,$A14,'Base Bruta'!$S$5:$S$145,"Sim") -> 0 | F14: =IFERROR(D14/B14,0) -> 0 | G14: =IFERROR(E14/B14,0) -> 0 | H14: =SUMIFS('Base Bruta'!$H$5:$H$145,'Base Bruta'!$B$5:$B$145,$A14,'Base Bruta'!$S$5:$S$145,"Sim")*Dashboard!$B$5 -> 0 | I14: =SUMIFS('Base Bruta'!$J$5:$J$145,'Base Bruta'!$B$5:$B$145,$A14,'Base Bruta'!$S$5:$S$145,"Sim")*Dashboard!$B$5 -> 0 | J14: =IFERROR(H14/D14,0) -> 0 | K14: =IFERROR(I14/D14,0) -> 0 | L14: =I14-H14 -> 0 | M14: =SUMIFS('Base Bruta'!$L$5:$L$145,'Base Bruta'!$B$5:$B$145,$A14,'Base Bruta'!$S$5:$S$145,"Sim")*Dashboard!$B$5 -> 0 | N14: =SUMIFS('Base Bruta'!$N$5:$N$145,'Base Bruta'!$B$5:$B$145,$A14,'Base Bruta'!$S$5:$S$145,"Sim")*Dashboard!$B$5 -> 0 | O14: =M14+N14 -> 0 | P14: =IFERROR(O14/I14,0) -> 0 | Q14: =IFERROR(M14/O14,0) -> 0 | R14: =E14*Dashboard!$B$6 -> 0 | S14: =SUMIFS('Base Bruta'!$O$5:$O$145,'Base Bruta'!$B$5:$B$145,$A14,'Base Bruta'!$S$5:$S$145,"Sim")*Dashboard!$B$5 -> 0 | T14: =SUMIFS('Base Bruta'!$P$5:$P$145,'Base Bruta'!$B$5:$B$145,$A14,'Base Bruta'!$S$5:$S$145,"Sim")*Dashboard!$B$5 -> 0
A15: Mateus Caumo | B15: =SUMIFS('Base Bruta'!$F$5:$F$145,'Base Bruta'!$B$5:$B$145,$A15,'Base Bruta'!$S$5:$S$145,"Sim") -> 37161 | C15: =SUMIFS('Base Bruta'!$G$5:$G$145,'Base Bruta'!$B$5:$B$145,$A15,'Base Bruta'!$S$5:$S$145,"Sim") -> 1864 | D15: =SUMIFS('Base Bruta'!$I$5:$I$145,'Base Bruta'!$B$5:$B$145,$A15,'Base Bruta'!$S$5:$S$145,"Sim") -> 1191 | E15: =SUMIFS('Base Bruta'!$Q$5:$Q$145,'Base Bruta'!$B$5:$B$145,$A15,'Base Bruta'!$S$5:$S$145,"Sim") -> 677 | F15: =IFERROR(D15/B15,0) -> 0.03204973 | G15: =IFERROR(E15/B15,0) -> 0.018218024 | H15: =SUMIFS('Base Bruta'!$H$5:$H$145,'Base Bruta'!$B$5:$B$145,$A15,'Base Bruta'!$S$5:$S$145,"Sim")*Dashboard!$B$5 -> 57362.296 | I15: =SUMIFS('Base Bruta'!$J$5:$J$145,'Base Bruta'!$B$5:$B$145,$A15,'Base Bruta'!$S$5:$S$145,"Sim")*Dashboard!$B$5 -> 121282.35 | J15: =IFERROR(H15/D15,0) -> 48.163137 | K15: =IFERROR(I15/D15,0) -> 101.83236 | L15: =I15-H15 -> 63920.049 | M15: =SUMIFS('Base Bruta'!$L$5:$L$145,'Base Bruta'!$B$5:$B$145,$A15,'Base Bruta'!$S$5:$S$145,"Sim")*Dashboard!$B$5 -> 23496.515 | N15: =SUMIFS('Base Bruta'!$N$5:$N$145,'Base Bruta'!$B$5:$B$145,$A15,'Base Bruta'!$S$5:$S$145,"Sim")*Dashboard!$B$5 -> 179005.91 | O15: =M15+N15 -> 202502.43 | P15: =IFERROR(O15/I15,0) -> 1.6696777 | Q15: =IFERROR(M15/O15,0) -> 0.11603078 | R15: =E15*Dashboard!$B$6 -> 108320 | S15: =SUMIFS('Base Bruta'!$O$5:$O$145,'Base Bruta'!$B$5:$B$145,$A15,'Base Bruta'!$S$5:$S$145,"Sim")*Dashboard!$B$5 -> 31804.031 | T15: =SUMIFS('Base Bruta'!$P$5:$P$145,'Base Bruta'!$B$5:$B$145,$A15,'Base Bruta'!$S$5:$S$145,"Sim")*Dashboard!$B$5 -> 7656.7625
A16: Menezes | B16: =SUMIFS('Base Bruta'!$F$5:$F$145,'Base Bruta'!$B$5:$B$145,$A16,'Base Bruta'!$S$5:$S$145,"Sim") -> 1 | C16: =SUMIFS('Base Bruta'!$G$5:$G$145,'Base Bruta'!$B$5:$B$145,$A16,'Base Bruta'!$S$5:$S$145,"Sim") -> 0 | D16: =SUMIFS('Base Bruta'!$I$5:$I$145,'Base Bruta'!$B$5:$B$145,$A16,'Base Bruta'!$S$5:$S$145,"Sim") -> 0 | E16: =SUMIFS('Base Bruta'!$Q$5:$Q$145,'Base Bruta'!$B$5:$B$145,$A16,'Base Bruta'!$S$5:$S$145,"Sim") -> 0 | F16: =IFERROR(D16/B16,0) -> 0 | G16: =IFERROR(E16/B16,0) -> 0 | H16: =SUMIFS('Base Bruta'!$H$5:$H$145,'Base Bruta'!$B$5:$B$145,$A16,'Base Bruta'!$S$5:$S$145,"Sim")*Dashboard!$B$5 -> 0 | I16: =SUMIFS('Base Bruta'!$J$5:$J$145,'Base Bruta'!$B$5:$B$145,$A16,'Base Bruta'!$S$5:$S$145,"Sim")*Dashboard!$B$5 -> 0 | J16: =IFERROR(H16/D16,0) -> 0 | K16: =IFERROR(I16/D16,0) -> 0 | L16: =I16-H16 -> 0 | M16: =SUMIFS('Base Bruta'!$L$5:$L$145,'Base Bruta'!$B$5:$B$145,$A16,'Base Bruta'!$S$5:$S$145,"Sim")*Dashboard!$B$5 -> 0 | N16: =SUMIFS('Base Bruta'!$N$5:$N$145,'Base Bruta'!$B$5:$B$145,$A16,'Base Bruta'!$S$5:$S$145,"Sim")*Dashboard!$B$5 -> 0 | O16: =M16+N16 -> 0 | P16: =IFERROR(O16/I16,0) -> 0 | Q16: =IFERROR(M16/O16,0) -> 0 | R16: =E16*Dashboard!$B$6 -> 0 | S16: =SUMIFS('Base Bruta'!$O$5:$O$145,'Base Bruta'!$B$5:$B$145,$A16,'Base Bruta'!$S$5:$S$145,"Sim")*Dashboard!$B$5 -> 0 | T16: =SUMIFS('Base Bruta'!$P$5:$P$145,'Base Bruta'!$B$5:$B$145,$A16,'Base Bruta'!$S$5:$S$145,"Sim")*Dashboard!$B$5 -> 0
... A24: Welington da Bet | B24: =SUMIFS('Base Bruta'!$F$5:$F$145,'Base Bruta'!$B$5:$B$145,$A24,'Base Bruta'!$S$5:$S$145,"Sim") -> 280 | C24: =SUMIFS('Base Bruta'!$G$5:$G$145,'Base Bruta'!$B$5:$B$145,$A24,'Base Bruta'!$S$5:$S$145,"Sim") -> 38 | D24: =SUMIFS('Base Bruta'!$I$5:$I$145,'Base Bruta'!$B$5:$B$145,$A24,'Base Bruta'!$S$5:$S$145,"Sim") -> 9 | E24: =SUMIFS('Base Bruta'!$Q$5:$Q$145,'Base Bruta'!$B$5:$B$145,$A24,'Base Bruta'!$S$5:$S$145,"Sim") -> 5 | F24: =IFERROR(D24/B24,0) -> 0.032142857 | G24: =IFERROR(E24/B24,0) -> 0.017857143 | H24: =SUMIFS('Base Bruta'!$H$5:$H$145,'Base Bruta'!$B$5:$B$145,$A24,'Base Bruta'!$S$5:$S$145,"Sim")*Dashboard!$B$5 -> 475.654 | I24: =SUMIFS('Base Bruta'!$J$5:$J$145,'Base Bruta'!$B$5:$B$145,$A24,'Base Bruta'!$S$5:$S$145,"Sim")*Dashboard!$B$5 -> 550.1745 | J24: =IFERROR(H24/D24,0) -> 52.850444 | K24: =IFERROR(I24/D24,0) -> 61.1305 | L24: =I24-H24 -> 74.5205 | M24: =SUMIFS('Base Bruta'!$L$5:$L$145,'Base Bruta'!$B$5:$B$145,$A24,'Base Bruta'!$S$5:$S$145,"Sim")*Dashboard!$B$5 -> 1048.2825 | N24: =SUMIFS('Base Bruta'!$N$5:$N$145,'Base Bruta'!$B$5:$B$145,$A24,'Base Bruta'!$S$5:$S$145,"Sim")*Dashboard!$B$5 -> 275.731 | O24: =M24+N24 -> 1324.0135 | P24: =IFERROR(O24/I24,0) -> 2.4065337 | Q24: =IFERROR(M24/O24,0) -> 0.79174608 | R24: =E24*Dashboard!$B$6 -> 800 | S24: =SUMIFS('Base Bruta'!$O$5:$O$145,'Base Bruta'!$B$5:$B$145,$A24,'Base Bruta'!$S$5:$S$145,"Sim")*Dashboard!$B$5 -> 270.478 | T24: =SUMIFS('Base Bruta'!$P$5:$P$145,'Base Bruta'!$B$5:$B$145,$A24,'Base Bruta'!$S$5:$S$145,"Sim")*Dashboard!$B$5 -> 155.015
A25: TOTAL | B25: =SUM(B5:B24) -> 184120 | C25: =SUM(C5:C24) -> 7488 | D25: =SUM(D5:D24) -> 4421 | E25: =SUM(E5:E24) -> 2279 | F25: =IFERROR(D25/B25,0) -> 0.024011514 | G25: =IFERROR(E25/B25,0) -> 0.012377797 | H25: =SUM(H5:H24) -> 162542.24 | I25: =SUM(I5:I24) -> 314232.81 | J25: =IFERROR(H25/D25,0) -> 36.765944 | K25: =IFERROR(I25/D25,0) -> 71.077316 | L25: =I25-H25 -> 151690.57 | M25: =SUM(M5:M24) -> 88242.005 | N25: =SUM(N5:N24) -> 396619.11 | O25: =M25+N25 -> 484861.12 | P25: =IFERROR(O25/I25,0) -> 1.5429996 | Q25: =IFERROR(M25/O25,0) -> 0.18199439 | R25: =E25*Dashboard!$B$6 -> 364640 | S25: =SUM(S5:S24) -> 79346.102 | T25: =SUM(T5:T24) -> 19082.81

Sheet Landing Pages
A1: Performance por Landing Page — Funil de Conversao (R$)
A2: Visao de funil por landing page, valores em Reais. Sem alocacao de custo (CPA/RevShare sao por sub-afiliado, nao por LP).
A4: Landing Page | B4: Clicks | C4: Signups | D4: FTD (qtd) | E4: QFTD | F4: Conv. Total (Clique->FTD) | G4: Conv. QFTD (Clique->QFTD) | H4: Valor FTD (R$) | I4: Ticket Medio FTD (R$)
A5: AFF BetSlip 2 | Dupla Aposta | BR | B5: =SUMIFS('Base Bruta'!$F$5:$F$145,'Base Bruta'!$C$5:$C$145,$A5,'Base Bruta'!$S$5:$S$145,"Sim") -> 168407 | C5: =SUMIFS('Base Bruta'!$G$5:$G$145,'Base Bruta'!$C$5:$C$145,$A5,'Base Bruta'!$S$5:$S$145,"Sim") -> 4477 | D5: =SUMIFS('Base Bruta'!$I$5:$I$145,'Base Bruta'!$C$5:$C$145,$A5,'Base Bruta'!$S$5:$S$145,"Sim") -> 2842 | E5: =SUMIFS('Base Bruta'!$Q$5:$Q$145,'Base Bruta'!$C$5:$C$145,$A5,'Base Bruta'!$S$5:$S$145,"Sim") -> 1276 | F5: =IFERROR(D5/B5,0) -> 0.016875783 | G5: =IFERROR(E5/B5,0) -> 0.0075768822 | H5: =SUMIFS('Base Bruta'!$H$5:$H$145,'Base Bruta'!$C$5:$C$145,$A5,'Base Bruta'!$S$5:$S$145,"Sim")*Dashboard!$B$5 -> 104311.91 | I5: =IFERROR(H5/D5,0) -> 36.703698
A6: AFF BetSlip | Dupla Aposta | BR | B6: =SUMIFS('Base Bruta'!$F$5:$F$145,'Base Bruta'!$C$5:$C$145,$A6,'Base Bruta'!$S$5:$S$145,"Sim") -> 26 | C6: =SUMIFS('Base Bruta'!$G$5:$G$145,'Base Bruta'!$C$5:$C$145,$A6,'Base Bruta'!$S$5:$S$145,"Sim") -> 2 | D6: =SUMIFS('Base Bruta'!$I$5:$I$145,'Base Bruta'!$C$5:$C$145,$A6,'Base Bruta'!$S$5:$S$145,"Sim") -> 2 | E6: =SUMIFS('Base Bruta'!$Q$5:$Q$145,'Base Bruta'!$C$5:$C$145,$A6,'Base Bruta'!$S$5:$S$145,"Sim") -> 2 | F6: =IFERROR(D6/B6,0) -> 0.076923077 | G6: =IFERROR(E6/B6,0) -> 0.076923077 | H6: =SUMIFS('Base Bruta'!$H$5:$H$145,'Base Bruta'!$C$5:$C$145,$A6,'Base Bruta'!$S$5:$S$145,"Sim")*Dashboard!$B$5 -> 99.498 | I6: =IFERROR(H6/D6,0) -> 49.749
A7: AFF | Dupla Aposta | BR | B7: =SUMIFS('Base Bruta'!$F$5:$F$145,'Base Bruta'!$C$5:$C$145,$A7,'Base Bruta'!$S$5:$S$145,"Sim") -> 15687 | C7: =SUMIFS('Base Bruta'!$G$5:$G$145,'Base Bruta'!$C$5:$C$145,$A7,'Base Bruta'!$S$5:$S$145,"Sim") -> 3009 | D7: =SUMIFS('Base Bruta'!$I$5:$I$145,'Base Bruta'!$C$5:$C$145,$A7,'Base Bruta'!$S$5:$S$145,"Sim") -> 1577 | E7: =SUMIFS('Base Bruta'!$Q$5:$Q$145,'Base Bruta'!$C$5:$C$145,$A7,'Base Bruta'!$S$5:$S$145,"Sim") -> 1001 | F7: =IFERROR(D7/B7,0) -> 0.1005291 | G7: =IFERROR(E7/B7,0) -> 0.063810799 | H7: =SUMIFS('Base Bruta'!$H$5:$H$145,'Base Bruta'!$C$5:$C$145,$A7,'Base Bruta'!$S$5:$S$145,"Sim")*Dashboard!$B$5 -> 58130.831 | I7: =IFERROR(H7/D7,0) -> 36.861656
A8: TOTAL | B8: =SUM(B5:B7) -> 184120 | C8: =SUM(C5:C7) -> 7488 | D8: =SUM(D5:D7) -> 4421 | E8: =SUM(E5:E7) -> 2279 | F8: =IFERROR(D8/B8,0) -> 0.024011514 | G8: =IFERROR(E8/B8,0) -> 0.012377797 | H8: =SUM(H5:H7) -> 162542.24 | I8: =IFERROR(H8/D8,0) -> 36.765944
